from fastapi import APIRouter, HTTPException, status, Depends
from schemas.day import Day as day_schema
from config.db import get_db,Session
from models.days import Days as day_models
from auth.auth_bearer import JWTBearer

router =  APIRouter(prefix='/days', dependencies=[Depends(JWTBearer())], tags=['Days'], responses={404 : {'message' : 'Not found'}})

@router.get("/", response_model = list[day_schema])
async def get_days():
    try:#instrucción try, atrapa de inicio a fin las lineas que intentaremos ejecutar y que tiene posibilidad de fallar
    #¡inicio try!
        session = get_db()
        db:Session
        for db in session:
            #se usa la instrucción where para buscar por el id y se ejecuta el first para
            #encontrar la primera coincidencia, esto es posible porque el id es un 
            #identificador unico
            r=db.query(day_models)
            return r
    #¡fin try!
    except Exception as e:#instrucción que nos ayuda a atrapar la excepción que ocurre cuando alguna instrucción dentro de try falla
        #se debe controlar siempre que nos conectamos a una base de datos con un try - except
        #debido a que no podemos controlar la respuesta del servicio externo (en este caso la base de datos)
        #y es muy posible que la conexión falle por lo cual debemos responder que paso
        raise HTTPException(status_code=status.HTTP_400_BAD_REQUEST,detail=str(e))
        #la instrucción raise es similar a la instrucción return, pero en vez de retornar cualquier elemento, retornamos especificamente
        #un error, en este caso el error esta contenido en HTTPException

@router.get("/{id}", response_model = day_schema)
async def read_day(id: str):
    try:#instrucción try, atrapa de inicio a fin las lineas que intentaremos ejecutar y que tiene posibilidad de fallar
    #¡inicio try!
        session = get_db()
        db:Session
        for db in session:
            #se usa la instrucción where para buscar por el id y se ejecuta el first para
            #encontrar la primera coincidencia, esto es posible porque el id es un 
            #identificador unico
            r=db.query(day_models).where(day_models.uuid_day == id).first()            
            return r
    #¡fin try!
    except Exception as e:#instrucción que nos ayuda a atrapar la excepción que ocurre cuando alguna instrucción dentro de try falla
        #se debe controlar siempre que nos conectamos a una base de datos con un try - except
        #debido a que no podemos controlar la respuesta del servicio externo (en este caso la base de datos)
        #y es muy posible que la conexión falle por lo cual debemos responder que paso
        raise HTTPException(status_code=status.HTTP_400_BAD_REQUEST,detail=str(e))
        #la instrucción raise es similar a la instrucción return, pero en vez de retornar cualquier elemento, retornamos especificamente
        #un error, en este caso el error esta contenido en HTTPException
