from fastapi import APIRouter, Response, HTTPException, status, Depends
from sqlalchemy import desc
from app.schemas.role import Role as role_schema
from app.schemas.role import Role_response as role_schema_response
from app.config.db import get_db,Session
from app.models.role import Role as role_model
import uuid
import typing
from datetime import datetime
from app.auth.auth_bearer import JWTBearer

router =  APIRouter(prefix='/roles', dependencies=[Depends(JWTBearer())], tags=['Roles'], responses={404 : {'message' : 'Not found'}})

@router.post("/", response_model=role_schema_response)
def create_rol(role_obj:role_schema):
    try:#instrucción try, atrapa de inicio a fin las lineas que intentaremos ejecutar y que tiene posibilidad de fallar
    #¡inicio try!
        session = get_db()
        db:Session
        for db in session:
            #role_obj["id"] = uuid.uuid4() 
            # print(type('esto es', role_obj))           
            role_obj = role_model(**role_obj.model_dump())  
            role_obj.uuid_rol = uuid.uuid4()
            role_obj.created_at = datetime.today().strftime('%Y-%m-%d %H:%M:%S')          
            #añade el recurso persona para subirse a la base de datos
            db.add(role_obj)
            #se sube a la base de datos
            db.commit()
            #se refresca la información en la variable persona para poderla devolver
            #en el servicio
            db.refresh(role_obj)
            return role_obj
    #¡fin try!
    except Exception as e: #instrucción que nos ayuda a atrapar la excepción que ocurre cuando alguna instrucción dentro de try falla
        #se debe controlar siempre que nos conectamos a una base de datos con un try - except
        #debido a que no podemos controlar la respuesta del servicio externo (en este caso la base de datos)
        #y es muy posible que la conexión falle por lo cual debemos responder que paso
        raise HTTPException(status_code=status.HTTP_400_BAD_REQUEST,detail=str(e))
        #la instrucción raise es similar a la instrucción return, pero en vez de retornar cualquier elemento, retornamos especificamente
        #un error, en este caso el error esta contenido en HTTPException

@router.get("/all", response_model = typing.List[role_schema_response])
def get_rols():
    try:#instrucción try, atrapa de inicio a fin las lineas que intentaremos ejecutar y que tiene posibilidad de fallar
    #¡inicio try!
        session = get_db()
        db:Session
        for db in session:
            #se usa la instrucción where para buscar por el id y se ejecuta el first para
            #encontrar la primera coincidencia, esto es posible porque el id es un 
            #identificador unico
            r=db.query(role_model).order_by(desc(role_model.created_at)).all()
            return r
    #¡fin try!
    except Exception as e:
        raise HTTPException(status_code=status.HTTP_400_BAD_REQUEST,detail=str(e))

@router.get("/{uuid_role}", response_model = role_schema_response)
def read_rol(uuid_role: str):
    try:#instrucción try, atrapa de inicio a fin las lineas que intentaremos ejecutar y que tiene posibilidad de fallar
    #¡inicio try!
        session = get_db()
        db:Session
        for db in session:
            #se usa la instrucción where para buscar por el id y se ejecuta el first para
            #encontrar la primera coincidencia, esto es posible porque el id es un 
            #identificador unico
            r=db.query(role_model).where(role_model.uuid_rol == uuid_role).first()
            return r
    #¡fin try!
    except Exception as e:#instrucción que nos ayuda a atrapar la excepción que ocurre cuando alguna instrucción dentro de try falla
        #se debe controlar siempre que nos conectamos a una base de datos con un try - except
        #debido a que no podemos controlar la respuesta del servicio externo (en este caso la base de datos)
        #y es muy posible que la conexión falle por lo cual debemos responder que paso
        raise HTTPException(status_code=status.HTTP_400_BAD_REQUEST,detail=str(e))
        #la instrucción raise es similar a la instrucción return, pero en vez de retornar cualquier elemento, retornamos especificamente
        #un error, en este caso el error esta contenido en HTTPException
    
@router.delete("/{uuid_role}")
def delete_rol(uuid_role: str):
    try:#instrucción try, atrapa de inicio a fin las lineas que intentaremos ejecutar y que tiene posibilidad de fallar
    #¡inicio try!
        #si falla, se detendrá el flujo común y se ejecutará las instrucciones del except
        session = get_db()
        db:Session
        for db in session:
            #one or none es una
            r=db.query(role_model).where(role_model.uuid_rol == uuid_role).one_or_none()
            if r is not None:
                db.delete(r)#instruccion para borrar un recurso
                db.commit()
                return Response(status_code=status.HTTP_204_NO_CONTENT)
            else:
                return Response(status_code=status.HTTP_404_NOT_FOUND)
    #¡fin try!
    except Exception as e: #instrucción que nos ayuda a atrapar la excepción que ocurre cuando alguna instrucción dentro de try falla
        #se debe controlar siempre que nos conectamos a una base de datos con un try - except
        #debido a que no podemos controlar la respuesta del servicio externo (en este caso la base de datos)
        #y es muy posible que la conexión falle por lo cual debemos responder que paso
        raise HTTPException(status_code=status.HTTP_400_BAD_REQUEST,detail=str(e))
        #la instrucción raise es similar a la instrucción return, pero en vez de retornar cualquier elemento, retornamos especificamente
        #un error, en este caso el error esta contenido en HTTPException            }